Time slot   0
ld_routine
Time slot   1
	Loaded a process at input/proc/p1s, PID: 1 PRIO: 15
	CPU 3: Dispatched process  1
Time slot   2
Time slot   3
	CPU 3: Put process  1 to run queue
	CPU 3: Dispatched process  1
Time slot   4
	Loaded a process at input/proc/m0s, PID: 2 PRIO: 120
	CPU 3: Put process  1 to run queue
Time slot   5
	CPU 3: Dispatched process  1
	CPU 2: Dispatched process  2

--- PAGE TABLE DUMP OF PROCESS 2 ---
PGN 000: Present=1, Swapped=0, FPN=0 (RAM)
-------------------------------------
Time slot   6

--- PAGE TABLE DUMP OF PROCESS 2 ---
PGN 000: Present=1, Swapped=0, FPN=0 (RAM)
-------------------------------------
Time slot   7
	CPU 2: Put process  2 to run queue
	CPU 2: Dispatched process  2
libfree:206

--- PAGE TABLE DUMP OF PROCESS 2 ---
PGN 000: Present=1, Swapped=0, FPN=0 (RAM)
-------------------------------------
	Loaded a process at input/proc/p0s, PID: 3 PRIO: 130
	CPU 3: Put process  1 to run queue
	CPU 3: Dispatched process  1
Time slot   8
	CPU 1: Dispatched process  3

--- PAGE TABLE DUMP OF PROCESS 2 ---
PGN 000: Present=1, Swapped=0, FPN=2 (RAM)
-------------------------------------
Time slot   9

--- PAGE TABLE DUMP OF PROCESS 3 ---
PGN 000: Present=1, Swapped=0, FPN=2 (RAM)
-------------------------------------
	CPU 2: Put process  2 to run queue
	CPU 2: Dispatched process  2

--- PAGE TABLE DUMP OF PROCESS 2 ---
PGN 000: Present=1, Swapped=0, FPN=2 (RAM)
-------------------------------------
	Loaded a process at input/proc/s0, PID: 4 PRIO: 38
	CPU 3: Put process  1 to run queue
	CPU 3: Dispatched process  1
Time slot  10
	CPU 0: Dispatched process  4
	CPU 1: Put process  3 to run queue
	CPU 1: Dispatched process  3

--- PAGE TABLE DUMP OF PROCESS 2 ---
-------------------------------------

--- PAGE TABLE DUMP OF PROCESS 3 ---
PGN 000: Present=1, Swapped=0, FPN=4 (RAM)
-------------------------------------
Time slot  11
	CPU 2: Processed  2 has finished
	CPU 3: Processed  1 has finished
	Loaded a process at input/proc/s3, PID: 5 PRIO: 39
	CPU 2: Dispatched process  5
Time slot  12
	CPU 0: Put process  4 to run queue
	CPU 0: Dispatched process  4
	CPU 1: Put process  3 to run queue
	CPU 1: Dispatched process  3

--- PAGE TABLE DUMP OF PROCESS 3 ---
PGN 000: Present=1, Swapped=0, FPN=6 (RAM)
-------------------------------------
Time slot  13

--- PAGE TABLE DUMP OF PROCESS 3 ---
PGN 000: Present=1, Swapped=0, FPN=6 (RAM)
-------------------------------------
	Loaded a process at input/proc/m1s, PID: 6 PRIO: 15
	CPU 2: Put process  5 to run queue
	CPU 2: Dispatched process  6
Time slot  14

--- PAGE TABLE DUMP OF PROCESS 6 ---
PGN 000: Present=1, Swapped=0, FPN=7 (RAM)
-------------------------------------
	CPU 0: Put process  4 to run queue
	CPU 0: Dispatched process  4
	CPU 3: Dispatched process  5
	CPU 1: Put process  3 to run queue
	CPU 1: Dispatched process  3
libread:362

--- PAGE TABLE DUMP OF PROCESS 3 ---
PGN 000: Present=1, Swapped=0, FPN=7 (RAM)
-------------------------------------
Time slot  15

--- PAGE TABLE DUMP OF PROCESS 6 ---
PGN 000: Present=1, Swapped=0, FPN=7 (RAM)
-------------------------------------

--- PAGE TABLE DUMP OF PROCESS 3 ---
PGN 000: Present=1, Swapped=0, FPN=7 (RAM)
-------------------------------------
	CPU 2: Put process  6 to run queue
	CPU 2: Dispatched process  6
Time slot  16
	CPU 0: Put process  4 to run queue
	CPU 0: Dispatched process  4
libfree:206

--- PAGE TABLE DUMP OF PROCESS 6 ---
PGN 000: Present=1, Swapped=0, FPN=7 (RAM)
-------------------------------------
	CPU 3: Put process  5 to run queue
	CPU 3: Dispatched process  5
	Loaded a process at input/proc/s2, PID: 7 PRIO: 120
	CPU 1: Put process  3 to run queue
	CPU 1: Dispatched process  7
Time slot  17

--- PAGE TABLE DUMP OF PROCESS 6 ---
PGN 000: Present=1, Swapped=0, FPN=9 (RAM)
-------------------------------------
	Loaded a process at input/proc/s1, PID: 8 PRIO: 0
Time slot  18
	CPU 0: Put process  4 to run queue
	CPU 0: Dispatched process  8
	CPU 2: Put process  6 to run queue
	CPU 2: Dispatched process  6
	CPU 3: Put process  5 to run queue
	CPU 3: Dispatched process  4
	CPU 1: Put process  7 to run queue
	CPU 1: Dispatched process  5
Time slot  19
	CPU 2: Processed  6 has finished
	CPU 2: Dispatched process  7
Time slot  20
	CPU 3: Put process  4 to run queue
	CPU 3: Dispatched process  4
	CPU 1: Put process  5 to run queue
	CPU 1: Dispatched process  5
	CPU 0: Put process  8 to run queue
	CPU 0: Dispatched process  8
Time slot  21
	CPU 3: Put process  4 to run queue
	CPU 2: Put process  7 to run queue
	CPU 3: Dispatched process  4
	CPU 2: Dispatched process  7
Time slot  22
	CPU 0: Put process  8 to run queue
	CPU 0: Dispatched process  8
	CPU 1: Put process  5 to run queue
	CPU 1: Dispatched process  5
Time slot  23
	CPU 1: Processed  5 has finished
	CPU 1: Dispatched process  3
libread:362

--- PAGE TABLE DUMP OF PROCESS 3 ---
PGN 000: Present=1, Swapped=0, FPN=10 (RAM)
-------------------------------------
	CPU 2: Put process  7 to run queue
	CPU 2: Dispatched process  7
Time slot  24
	CPU 0: Put process  8 to run queue
	CPU 0: Dispatched process  8
	CPU 3: Put process  4 to run queue
	CPU 3: Dispatched process  4

--- PAGE TABLE DUMP OF PROCESS 3 ---
PGN 000: Present=1, Swapped=0, FPN=10 (RAM)
-------------------------------------
	CPU 3: Processed  4 has finished
	CPU 3 stopped
Time slot  25
	CPU 0: Processed  8 has finished
	CPU 0 stopped
	CPU 1: Put process  3 to run queue
	CPU 1: Dispatched process  3
libread:362

--- PAGE TABLE DUMP OF PROCESS 3 ---
PGN 000: Present=1, Swapped=0, FPN=10 (RAM)
-------------------------------------
	CPU 2: Put process  7 to run queue
	CPU 2: Dispatched process  7
Time slot  26
Time slot  27
	CPU 1: Put process  3 to run queue
	CPU 1: Dispatched process  3
	CPU 2: Put process  7 to run queue
Time slot  28
	CPU 2: Dispatched process  7
Time slot  29
	CPU 1: Processed  3 has finished
	CPU 1 stopped
Time slot  30
	CPU 2: Processed  7 has finished
	CPU 2 stopped

[OS SHUTDOWN] Extracting system telemetry...

=========================================
      PHYSICAL MEMORY ACCESS STATS       
=========================================
Total Physical Reads  (RAM & SWAP): 3
Total Physical Writes (RAM & SWAP): 5
=========================================


=========================================
      MULTI-LEVEL PAGING STORAGE STATS   
=========================================
Total Allocated Tables: 29
Total Storage Size: 118784 Bytes (116.00 KB)
=========================================

