Time slot   0
ld_routine
	Loaded a process at input/proc/p0s, PID: 1 PRIO: 130
Time slot   1
	CPU 2: Dispatched process  1
Time slot   2
	CPU 2: Put process  1 to run queue
	CPU 2: Dispatched process  1
Time slot   3
	Loaded a process at input/proc/m0s, PID: 2 PRIO: 120
	CPU 1: Dispatched process  2
libfree:205
Time slot   4
	Loaded a process at input/proc/s1, PID: 3 PRIO: 0
	CPU 3: Dispatched process  3
	CPU 1: Put process  2 to run queue
	CPU 1: Dispatched process  2
Time slot   5
	CPU 2: Put process  1 to run queue
	CPU 2: Dispatched process  1
Time slot   6
	Loaded a process at input/proc/p1s, PID: 4 PRIO: 15
	CPU 0: Dispatched process  4
	CPU 3: Put process  3 to run queue
	CPU 3: Dispatched process  3
Time slot   7
	CPU 1: Put process  2 to run queue
	CPU 1: Dispatched process  2
	CPU 2: Put process  1 to run queue
	CPU 2: Dispatched process  1
libread:361
Time slot   8
	CPU 0: Put process  4 to run queue
	CPU 0: Dispatched process  4
	CPU 3: Put process  3 to run queue
	CPU 3: Dispatched process  3
	CPU 1: Processed  2 has finished
Time slot   9
	CPU 2: Put process  1 to run queue
	CPU 2: Dispatched process  1
libread:361
	Loaded a process at input/proc/s3, PID: 5 PRIO: 39
Time slot  10
	CPU 1: Dispatched process  5
	Loaded a process at input/proc/s2, PID: 6 PRIO: 120
	CPU 0: Put process  4 to run queue
	CPU 0: Dispatched process  4
	CPU 3: Put process  3 to run queue
	Loaded a process at input/proc/m1s, PID: 7 PRIO: 15
	CPU 3: Dispatched process  3
Time slot  11
	CPU 2: Put process  1 to run queue
	CPU 2: Dispatched process  7
	Loaded a process at input/proc/s0, PID: 8 PRIO: 38
	CPU 3: Processed  3 has finished
Time slot  12
	CPU 3: Dispatched process  8
	CPU 1: Put process  5 to run queue
	CPU 1: Dispatched process  5
	CPU 0: Put process  4 to run queue
	CPU 0: Dispatched process  4
	CPU 2: Put process  7 to run queue
	CPU 2: Dispatched process  7
Time slot  13
	CPU 3: Put process  8 to run queue
	CPU 3: Dispatched process  8
Time slot  14
	CPU 0: Put process  4 to run queue
	CPU 0: Dispatched process  4
	CPU 1: Put process  5 to run queue
	CPU 1: Dispatched process  5
	CPU 2: Put process  7 to run queue
	CPU 2: Dispatched process  7
libfree:205
Time slot  15
	CPU 3: Put process  8 to run queue
	CPU 3: Dispatched process  8
libfree:205
	CPU 1: Put process  5 to run queue
	CPU 0: Processed  4 has finished
	CPU 1: Dispatched process  5
	CPU 0: Dispatched process  6
Time slot  16
Time slot  17
	CPU 2: Processed  7 has finished
	CPU 2: Dispatched process  1
libread:361
	CPU 3: Put process  8 to run queue
	CPU 3: Dispatched process  8
Time slot  18
	CPU 0: Put process  6 to run queue
	CPU 0: Dispatched process  6
	CPU 1: Put process  5 to run queue
	CPU 1: Dispatched process  5
	CPU 2: Put process  1 to run queue
	CPU 2: Dispatched process  1
Time slot  19
	CPU 3: Put process  8 to run queue
	CPU 3: Dispatched process  8
	CPU 1: Put process  5 to run queue
	CPU 1: Dispatched process  5
Time slot  20
	CPU 0: Put process  6 to run queue
	CPU 0: Dispatched process  6
	CPU 2: Processed  1 has finished
	CPU 2 stopped
	CPU 1: Processed  5 has finished
	CPU 1 stopped
Time slot  21
Time slot  22
	CPU 0: Put process  6 to run queue
	CPU 0: Dispatched process  6
	CPU 3: Put process  8 to run queue
	CPU 3: Dispatched process  8
Time slot  23
	CPU 3: Put process  8 to run queue
	CPU 3: Dispatched process  8
Time slot  24
	CPU 0: Put process  6 to run queue
	CPU 0: Dispatched process  6
Time slot  25
	CPU 3: Put process  8 to run queue
	CPU 3: Dispatched process  8
Time slot  26
	CPU 0: Put process  6 to run queue
	CPU 0: Dispatched process  6
	CPU 3: Processed  8 has finished
	CPU 3 stopped
Time slot  27
Time slot  28
	CPU 0: Processed  6 has finished
	CPU 0 stopped

[OS SHUTDOWN] Extracting system telemetry...

=========================================
      PHYSICAL MEMORY ACCESS STATS       
=========================================
Total Physical Reads  (RAM & SWAP): 2
Total Physical Writes (RAM & SWAP): 5
=========================================


=========================================
      MULTI-LEVEL PAGING STORAGE STATS   
=========================================
Total Allocated Tables: 25
Total Storage Size: 102400 Bytes (100.00 KB)
=========================================

